<?xml version="1.0" ?>
<!-- =================================================================================== -->
<!-- |    This document was autogenerated by xacro from mircobot.urdf.xacro            | -->
<!-- |    EDITING THIS FILE BY HAND IS NOT RECOMMENDED                                 | -->
<!-- =================================================================================== -->
<robot name="mircobot">
  <material name="silver">
    <color rgba="0.700 0.700 0.700 1.000"/>
  </material>
  <link name="base_link">
    <inertial>
      <origin rpy="0 0 0" xyz="2.166333700984817e-17 1.0831668504924085e-17 0.02637499906536667"/>
      <mass value="6.591351466924831"/>
      <inertia ixx="0.006927" ixy="-0.0" ixz="0.0" iyy="0.015083" iyz="0.0" izz="0.01887"/>
    </inertial>
    <visual>
      <origin rpy="0 0 0" xyz="0 0 0"/>
      <geometry>
        <mesh filename="file:///home/saitama/mircobot4Wheel_ws/install/mircobot_description/share/mircobot_description/meshes/base_link.stl" scale="0.001 0.001 0.001"/>
      </geometry>
      <material name="silver"/>
    </visual>
    <collision>
      <origin rpy="0 0 0" xyz="0 0 0"/>
      <geometry>
        <mesh filename="file:///home/saitama/mircobot4Wheel_ws/install/mircobot_description/share/mircobot_description/meshes/base_link.stl" scale="0.001 0.001 0.001"/>
      </geometry>
    </collision>
  </link>
  <!-- BASE_FOOTPRINT LINK -->
  <joint name="base_footprint_joint" type="fixed">
    <parent link="base_link"/>
    <child link="base_footprint"/>
    <origin rpy="0 0 0" xyz="0 0 0"/>
  </joint>
  <link name="base_footprint">
</link>
  <joint name="wheel_front_left_joint" type="fixed">
    <origin rpy="-1.5708 0 0" xyz="0.05 0.065 0.025"/>
    <parent link="base_link"/>
    <child link="wheel_front_left_1"/>
    <axis xyz="0.0 0.0 1.0"/>
  </joint>
  <link name="wheel_front_left_1">
    <inertial>
      <origin rpy="0 0 0" xyz="-1.3877787807814457e-17 0.012499999999999997 0.0"/>
      <mass value="0.5548838024402973"/>
      <inertia ixx="0.000154" ixy="-0.0" ixz="0.0" iyy="0.00025" iyz="0.0" izz="0.000154"/>
    </inertial>
    <visual>
      <origin rpy="-1.5708 0 0" xyz="-0.05 -0.025 0.090"/>
      <geometry>
        <mesh filename="file:///home/saitama/mircobot4Wheel_ws/install/mircobot_description/share/mircobot_description/meshes/wheel_front_left_1.stl" scale="0.001 0.001 0.001"/>
      </geometry>
      <material name="silver"/>
    </visual>
    <collision>
      <origin rpy="-1.5708 0 0" xyz="-0.05 -0.025 0.090"/>
      <geometry>
        <mesh filename="file:///home/saitama/mircobot4Wheel_ws/install/mircobot_description/share/mircobot_description/meshes/wheel_front_left_1.stl" scale="0.001 0.001 0.001"/>
      </geometry>
    </collision>
  </link>
  <joint name="wheel_back_left_joint" type="continuous">
    <origin rpy="-1.5708 0 0" xyz="-0.05 0.065 0.025"/>
    <parent link="base_link"/>
    <child link="wheel_back_left_1"/>
    <axis xyz="0.0 0.0 1.0"/>
  </joint>
  <link name="wheel_back_left_1">
    <inertial>
      <origin rpy="0 0 0" xyz="1.3877787807814457e-17 0.012499999999999997 0.0"/>
      <mass value="0.554883802440297"/>
      <inertia ixx="0.000154" ixy="0.0" ixz="-0.0" iyy="0.00025" iyz="-0.0" izz="0.000154"/>
    </inertial>
    <visual>
      <origin rpy="-1.5708 0 0" xyz="0.05 -0.025 0.090"/>
      <geometry>
        <mesh filename="file:///home/saitama/mircobot4Wheel_ws/install/mircobot_description/share/mircobot_description/meshes/wheel_back_left_1.stl" scale="0.001 0.001 0.001"/>
      </geometry>
      <material name="silver"/>
    </visual>
    <collision>
      <origin rpy="-1.5708 0 0" xyz="0.05 -0.025 0.090"/>
      <geometry>
        <mesh filename="file:///home/saitama/mircobot4Wheel_ws/install/mircobot_description/share/mircobot_description/meshes/wheel_back_left_1.stl" scale="0.001 0.001 0.001"/>
      </geometry>
    </collision>
  </link>
  <joint name="wheel_front_right_joint" type="fixed">
    <origin rpy="-1.5708 0 0" xyz="0.05 -0.065 0.025"/>
    <parent link="base_link"/>
    <child link="wheel_front_right_1"/>
    <axis xyz="0.0 0.0 1.0"/>
  </joint>
  <link name="wheel_front_right_1">
    <inertial>
      <origin rpy="0 0 0" xyz="-1.3877787807814457e-17 -0.012499999999999997 0.0"/>
      <mass value="0.5548838024402969"/>
      <inertia ixx="0.000154" ixy="0.0" ixz="-0.0" iyy="0.00025" iyz="0.0" izz="0.000154"/>
    </inertial>
    <visual>
      <origin rpy="1.5708 0 0" xyz="-0.05 0.025 0.065"/>
      <geometry>
        <mesh filename="file:///home/saitama/mircobot4Wheel_ws/install/mircobot_description/share/mircobot_description/meshes/wheel_front_right_1.stl" scale="0.001 0.001 0.001"/>
      </geometry>
      <material name="silver"/>
    </visual>
    <collision>
      <origin rpy="1.5708 0 0" xyz="-0.05 0.025 0.065"/>
      <geometry>
        <mesh filename="file:///home/saitama/mircobot4Wheel_ws/install/mircobot_description/share/mircobot_description/meshes/wheel_front_right_1.stl" scale="0.001 0.001 0.001"/>
      </geometry>
    </collision>
  </link>
  <joint name="wheel_back_right_joint" type="continuous">
    <origin rpy="-1.5708 0 0" xyz="-0.05 -0.065 0.025"/>
    <parent link="base_link"/>
    <child link="wheel_back_right_1"/>
    <axis xyz="0.0 0.0 1.0"/>
  </joint>
  <link name="wheel_back_right_1">
    <inertial>
      <origin rpy="0 0 0" xyz="1.3877787807814457e-17 -0.012499999999999997 0.0"/>
      <mass value="0.554883802440297"/>
      <inertia ixx="0.000154" ixy="-0.0" ixz="-0.0" iyy="0.00025" iyz="0.0" izz="0.000154"/>
    </inertial>
    <visual>
      <origin rpy="1.5708 0 0" xyz="0.05 0.025 0.065"/>
      <geometry>
        <mesh filename="file:///home/saitama/mircobot4Wheel_ws/install/mircobot_description/share/mircobot_description/meshes/wheel_back_right_1.stl" scale="0.001 0.001 0.001"/>
      </geometry>
      <material name="silver"/>
    </visual>
    <collision>
      <origin rpy="1.5708 0 0" xyz="0.05 0.025 0.065"/>
      <geometry>
        <mesh filename="file:///home/saitama/mircobot4Wheel_ws/install/mircobot_description/share/mircobot_description/meshes/wheel_back_right_1.stl" scale="0.001 0.001 0.001"/>
      </geometry>
    </collision>
  </link>
  <joint name="lidar_joint" type="fixed">
    <origin rpy="0 0 0" xyz="0.0 0.0 0.06"/>
    <parent link="base_link"/>
    <child link="lidar_1"/>
  </joint>
  <link name="lidar_1">
    <inertial>
      <origin rpy="0 0 0" xyz="-1.7763568394002505e-17 -7.385233546074017e-18 0.010000000000000009"/>
      <mass value="0.6042068071016569"/>
      <inertia ixx="0.000205" ixy="0.0" ixz="-0.0" iyy="0.000205" iyz="-0.0" izz="0.00037"/>
    </inertial>
    <visual>
      <origin rpy="0 0 0" xyz="-0.0 -0.0 -0.06"/>
      <geometry>
        <mesh filename="file:///home/saitama/mircobot4Wheel_ws/install/mircobot_description/share/mircobot_description/meshes/lidar_1.stl" scale="0.001 0.001 0.001"/>
      </geometry>
      <material name="silver"/>
    </visual>
    <collision>
      <origin rpy="0 0 0" xyz="-0.0 -0.0 -0.06"/>
      <geometry>
        <mesh filename="file:///home/saitama/mircobot4Wheel_ws/install/mircobot_description/share/mircobot_description/meshes/lidar_1.stl" scale="0.001 0.001 0.001"/>
      </geometry>
    </collision>
  </link>
  <joint name="camera_joint" type="fixed">
    <origin rpy="0 0 0" xyz="0.08 0.0 0.025"/>
    <parent link="base_link"/>
    <child link="camera_1"/>
  </joint>
  <link name="camera_1">
    <inertial>
      <origin rpy="0 0 0" xyz="0.003320619451694526 -1.050959940980693e-29 0.009999999999914189"/>
      <mass value="0.018782687791334844"/>
      <inertia ixx="1e-06" ixy="-0.0" ixz="-0.0" iyy="1e-06" iyz="0.0" izz="1e-06"/>
    </inertial>
    <visual>
      <origin rpy="0 0 0" xyz="-0.08 -0.0 -0.025"/>
      <geometry>
        <mesh filename="file:///home/saitama/mircobot4Wheel_ws/install/mircobot_description/share/mircobot_description/meshes/camera_1.stl" scale="0.001 0.001 0.001"/>
      </geometry>
      <material name="silver"/>
    </visual>
    <collision>
      <origin rpy="0 0 0" xyz="-0.08 -0.0 -0.025"/>
      <geometry>
        <mesh filename="file:///home/saitama/mircobot4Wheel_ws/install/mircobot_description/share/mircobot_description/meshes/camera_1.stl" scale="0.001 0.001 0.001"/>
      </geometry>
    </collision>
  </link>
  <joint name="camera_optical_joint" type="fixed">
    <parent link="camera_1"/>
    <child link="camera_optical"/>
    <origin rpy="0 0 0" xyz="0.01 0 0.01"/>
  </joint>
  <link name="camera_optical"/>
  <gazebo reference="base_link">
    <material>Gazebo/Red</material>
  </gazebo>
  <gazebo reference="wheel_front_left_1">
    <material>Gazebo/Black</material>
    <mu1 value="0.01"/>
    <mu2 value="0.01"/>
    <!-- <self_collide>true</self_collide> -->
  </gazebo>
  <gazebo reference="wheel_back_left_1">
    <material>Gazebo/Black</material>
    <mu1 value="0.5"/>
    <mu2 value="0.5"/>
    <self_collide>true</self_collide>
  </gazebo>
  <gazebo reference="wheel_front_right_1">
    <material>Gazebo/Black</material>
    <mu1 value="0.01"/>
    <mu2 value="0.01"/>
    <!-- <self_collide>true</self_collide> -->
  </gazebo>
  <gazebo reference="wheel_back_right_1">
    <material>Gazebo/Black</material>
    <mu1 value="0.5"/>
    <mu2 value="0.5"/>
    <self_collide>true</self_collide>
  </gazebo>
  <gazebo reference="lidar_1">
    <material>Gazebo/Black</material>
    <sensor name="laser" type="ray">
      <pose> 0 0 0 0 0 0 </pose>
      <visualize>true</visualize>
      <always_on>true</always_on>
      <enable_processing>true</enable_processing>
      <update_rate>10</update_rate>
      <ray>
        <scan>
          <horizontal>
            <samples>360</samples>
            <min_angle>-3.14</min_angle>
            <max_angle>3.14</max_angle>
          </horizontal>
        </scan>
        <range>
          <min>0.3</min>
          <max>12</max>
        </range>
      </ray>
      <plugin filename="libgazebo_ros_ray_sensor.so" name="laser_controller">
        <ros>
          <argument>~/out:=scan</argument>
        </ros>
        <output_type>sensor_msgs/LaserScan</output_type>
        <frame_name>lidar_1</frame_name>
      </plugin>
    </sensor>
  </gazebo>
  <gazebo reference="camera_1">
    <sensor name="camera" type="camera">
      <pose> 0 0 0 0 0 0 </pose>
      <visualize>true</visualize>
      <update_rate>0.0</update_rate>
      <camera name="head">
        <horizontal_fov>1.089</horizontal_fov>
        <image>
          <width>640</width>
          <height>640</height>
          <format>R8G8B8</format>
        </image>
        <clip>
          <near>0.05</near>
          <far>8.0</far>
        </clip>
      </camera>
      <plugin filename="libgazebo_ros_camera.so" name="camera_controller">
        <!-- <alwaysOn>true</alwaysOn>
          <update_rate>0.0</update_rate> -->
        <!-- <cameraName>mircobot/camera_optical</cameraName>
          <imageTopicName>image_raw</imageTopicName>
          <cameraInfoTopicName>camera_info</cameraInfoTopicName> -->
        <frame_name>camera_optical</frame_name>
      </plugin>
    </sensor>
  </gazebo>
  <ros2_control name="GazeboSystem" type="system">
    <hardware>
      <plugin>gazebo_ros2_control/GazeboSystem</plugin>
    </hardware>
    <!-- <joint name="wheel_front_left_joint">
            <command_interface name="velocity">
                <param name="min">-10</param>
                <param name="max">10</param>
            </command_interface>
            <state_interface name="velocity"/>
            <state_interface name="position"/>

        </joint> -->
    <joint name="wheel_back_left_joint">
      <command_interface name="velocity">
        <param name="min">-10</param>
        <param name="max">10</param>
      </command_interface>
      <state_interface name="velocity"/>
      <state_interface name="position"/>
    </joint>
    <!-- <joint name="wheel_front_right_joint">
            <command_interface name="velocity">
                <param name="min">-10</param>
                <param name="max">10</param>
            </command_interface>
            <state_interface name="velocity"/>
            <state_interface name="position"/>

        </joint> -->
    <joint name="wheel_back_right_joint">
      <command_interface name="velocity">
        <param name="min">-10</param>
        <param name="max">10</param>
      </command_interface>
      <state_interface name="velocity"/>
      <state_interface name="position"/>
    </joint>
  </ros2_control>
  <gazebo>
    <plugin filename="libgazebo_ros2_control.so" name="gazebo_ros2_control">
      <parameters>/home/saitama/mircobot4Wheel_ws/install/mircobot_description/share/mircobot_description/config/my_controllers.yaml</parameters>
    </plugin>
  </gazebo>
  <!-- <xacro:include filename="$(find mircobot_description)/urdf/mircobot_transmission.xacro"/> -->
</robot>
